sh: 0: Can't open /var/www/compagnieinterface/gunicorn_start
sh: 0: Can't open /var/www/compagnieinterface/gunicorn_start
sh: 0: Can't open /var/www/compagnieinterface/gunicorn_start
sh: 0: Can't open /var/www/compagnieinterface/gunicorn_start
gunicorn_start.sh: 6: .: Can't open ~/.virtualenvs/compagnieinterface/bin/activate
gunicorn_start.sh: 6: .: Can't open ~/.virtualenvs/compagnieinterface/bin/activate
gunicorn_start.sh: 6: .: Can't open ~/.virtualenvs/compagnieinterface/bin/activate
gunicorn_start.sh: 6: .: Can't open ~/.virtualenvs/compagnieinterface/bin/activate
gunicorn_start.sh: 6: .: Can't open ~/.virtualenvs/compagnieinterface/bin/activate
gunicorn_start.sh: 6: .: Can't open ~/.virtualenvs/compagnieinterface/bin/activate
gunicorn_start.sh: 6: .: Can't open ~/.virtualenvs/compagnieinterface/bin/activate
gunicorn_start.sh: 6: .: Can't open ~/.virtualenvs/compagnieinterface/bin/activate
gunicorn_start.sh: 6: .: Can't open ~/.virtualenvs/compagnieinterface/bin/activate
gunicorn_start.sh: 6: .: Can't open ~/.virtualenvs/compagnieinterface/bin/activate
gunicorn_start.sh: 6: .: Can't open ~/.virtualenvs/compagnieinterface/bin/activate
gunicorn_start.sh: 6: .: Can't open ~/.virtualenvs/compagnieinterface/bin/activate
gunicorn_start.sh: 6: .: Can't open ~/.virtualenvs/compagnieinterface/bin/activate
gunicorn_start.sh: 6: .: Can't open ~/.virtualenvs/compagnieinterface/bin/activate
gunicorn_start.sh: 6: .: Can't open ~/.virtualenvs/compagnieinterface/bin/activate
gunicorn_start.sh: 6: .: Can't open ~/.virtualenvs/compagnieinterface/bin/activate
gunicorn_start.sh: 6: .: Can't open ~/.virtualenvs/compagnieinterface/bin/activate
gunicorn_start.sh: 6: .: Can't open ~/.virtualenvs/compagnieinterface/bin/activate
gunicorn_start.sh: 6: .: Can't open ~/.virtualenvs/compagnieinterface/bin/activate
gunicorn_start.sh: 6: .: Can't open ~/.virtualenvs/compagnieinterface/bin/activate
[2016-01-14 09:28:46 -0500] [6977] [INFO] Starting gunicorn 19.3.0
[2016-01-14 09:28:46 -0500] [6977] [INFO] Listening at: http://127.0.0.1:8005 (6977)
[2016-01-14 09:28:46 -0500] [6977] [INFO] Using worker: sync
[2016-01-14 09:28:46 -0500] [6982] [INFO] Booting worker with pid: 6982
[2016-01-14 09:28:46 -0500] [6983] [INFO] Booting worker with pid: 6983
[2016-01-14 09:28:46 -0500] [6984] [INFO] Booting worker with pid: 6984
[2016-01-14 10:39:16 -0500] [6977] [INFO] Handling signal: term
[2016-01-14 15:39:16 +0000] [6984] [INFO] Worker exiting (pid: 6984)
[2016-01-14 15:39:16 +0000] [6982] [INFO] Worker exiting (pid: 6982)
[2016-01-14 15:39:16 +0000] [6983] [INFO] Worker exiting (pid: 6983)
[2016-01-14 10:39:16 -0500] [6977] [INFO] Shutting down: Master
gunicorn_start.sh: 6: .: Can't open ~/.virtualenvs/compagnieinterface/bin/activate
gunicorn_start.sh: 6: .: Can't open ~/.virtualenvs/compagnieinterface/bin/activate
gunicorn_start.sh: 6: .: Can't open ~/.virtualenvs/compagnieinterface/bin/activate
gunicorn_start.sh: 6: .: Can't open ~/.virtualenvs/compagnieinterface/bin/activate
gunicorn_start.sh: 6: .: Can't open ~/.virtualenvs/compagnieinterface/bin/activate
gunicorn_start.sh: 6: .: Can't open ~/.virtualenvs/compagnieinterface/bin/activate
gunicorn_start.sh: 6: .: Can't open ~/.virtualenvs/compagnieinterface/bin/activate
gunicorn_start.sh: 6: .: Can't open ~/.virtualenvs/compagnieinterface/bin/activate
gunicorn_start.sh: 6: .: Can't open ~/.virtualenvs/compagnieinterface/bin/activate
gunicorn_start.sh: 6: .: Can't open ~/.virtualenvs/compagnieinterface/bin/activate
gunicorn_start.sh: 6: .: Can't open ~/.virtualenvs/compagnieinterface/bin/activate
gunicorn_start.sh: 6: .: Can't open ~/.virtualenvs/compagnieinterface/bin/activate
sh: 0: Can't open ~/.virtualenvs/compagnieinterface/bin/activate
Exception in worker process:
Traceback (most recent call last):
  File "/usr/local/lib/python3.4/dist-packages/gunicorn/arbiter.py", line 507, in spawn_worker
    worker.init_process()
  File "/usr/local/lib/python3.4/dist-packages/gunicorn/workers/base.py", line 114, in init_process
    self.wsgi = self.app.wsgi()
  File "/usr/local/lib/python3.4/dist-packages/gunicorn/app/base.py", line 66, in wsgi
    self.callable = self.load()
  File "/usr/local/lib/python3.4/dist-packages/gunicorn/app/wsgiapp.py", line 65, in load
    return self.load_wsgiapp()
  File "/usr/local/lib/python3.4/dist-packages/gunicorn/app/wsgiapp.py", line 52, in load_wsgiapp
    return util.import_app(self.app_uri)
  File "/usr/local/lib/python3.4/dist-packages/gunicorn/util.py", line 356, in import_app
    __import__(module)
  File "/var/www/compagnieinterface/sandbox/wsgi.py", line 16, in <module>
    application = get_wsgi_application()
  File "/usr/local/lib/python3.4/dist-packages/django/core/wsgi.py", line 14, in get_wsgi_application
    django.setup()
  File "/usr/local/lib/python3.4/dist-packages/django/__init__.py", line 21, in setup
    apps.populate(settings.INSTALLED_APPS)
  File "/usr/local/lib/python3.4/dist-packages/django/apps/registry.py", line 108, in populate
    app_config.import_models(all_models)
  File "/usr/local/lib/python3.4/dist-packages/django/apps/config.py", line 202, in import_models
    self.models_module = import_module(models_module_name)
  File "/usr/lib/python3.4/importlib/__init__.py", line 109, in import_module
    return _bootstrap._gcd_import(name[level:], package, level)
  File "/var/www/compagnieinterface/spectacles_lieux_bdd/models.py", line 243, in <module>
    class EventsGroup(models.Model):
  File "/usr/local/lib/python3.4/dist-packages/django/db/models/base.py", line 170, in __new__
    new_class.add_to_class(obj_name, obj)
  File "/usr/local/lib/python3.4/dist-packages/django/db/models/base.py", line 299, in add_to_class
    value.contribute_to_class(cls, name)
TypeError: contribute_to_class() missing 1 required positional argument: 'name'
Traceback (most recent call last):
  File "/usr/local/lib/python3.4/dist-packages/gunicorn/arbiter.py", line 507, in spawn_worker
    worker.init_process()
  File "/usr/local/lib/python3.4/dist-packages/gunicorn/workers/base.py", line 114, in init_process
    self.wsgi = self.app.wsgi()
  File "/usr/local/lib/python3.4/dist-packages/gunicorn/app/base.py", line 66, in wsgi
    self.callable = self.load()
  File "/usr/local/lib/python3.4/dist-packages/gunicorn/app/wsgiapp.py", line 65, in load
    return self.load_wsgiapp()
  File "/usr/local/lib/python3.4/dist-packages/gunicorn/app/wsgiapp.py", line 52, in load_wsgiapp
    return util.import_app(self.app_uri)
  File "/usr/local/lib/python3.4/dist-packages/gunicorn/util.py", line 356, in import_app
    __import__(module)
  File "/var/www/compagnieinterface/sandbox/wsgi.py", line 16, in <module>
    application = get_wsgi_application()
  File "/usr/local/lib/python3.4/dist-packages/django/core/wsgi.py", line 14, in get_wsgi_application
    django.setup()
  File "/usr/local/lib/python3.4/dist-packages/django/__init__.py", line 21, in setup
    apps.populate(settings.INSTALLED_APPS)
  File "/usr/local/lib/python3.4/dist-packages/django/apps/registry.py", line 108, in populate
    app_config.import_models(all_models)
  File "/usr/local/lib/python3.4/dist-packages/django/apps/config.py", line 202, in import_models
    self.models_module = import_module(models_module_name)
  File "/usr/lib/python3.4/importlib/__init__.py", line 109, in import_module
    return _bootstrap._gcd_import(name[level:], package, level)
  File "/var/www/compagnieinterface/spectacles_lieux_bdd/models.py", line 243, in <module>
    class EventsGroup(models.Model):
  File "/usr/local/lib/python3.4/dist-packages/django/db/models/base.py", line 170, in __new__
    new_class.add_to_class(obj_name, obj)
  File "/usr/local/lib/python3.4/dist-packages/django/db/models/base.py", line 299, in add_to_class
    value.contribute_to_class(cls, name)
TypeError: contribute_to_class() missing 1 required positional argument: 'name'
Exception in worker process:
Traceback (most recent call last):
  File "/usr/local/lib/python3.4/dist-packages/gunicorn/arbiter.py", line 507, in spawn_worker
    worker.init_process()
  File "/usr/local/lib/python3.4/dist-packages/gunicorn/workers/base.py", line 114, in init_process
    self.wsgi = self.app.wsgi()
  File "/usr/local/lib/python3.4/dist-packages/gunicorn/app/base.py", line 66, in wsgi
    self.callable = self.load()
  File "/usr/local/lib/python3.4/dist-packages/gunicorn/app/wsgiapp.py", line 65, in load
    return self.load_wsgiapp()
  File "/usr/local/lib/python3.4/dist-packages/gunicorn/app/wsgiapp.py", line 52, in load_wsgiapp
    return util.import_app(self.app_uri)
  File "/usr/local/lib/python3.4/dist-packages/gunicorn/util.py", line 356, in import_app
    __import__(module)
  File "/var/www/compagnieinterface/sandbox/wsgi.py", line 16, in <module>
    application = get_wsgi_application()
  File "/usr/local/lib/python3.4/dist-packages/django/core/wsgi.py", line 14, in get_wsgi_application
    django.setup()
  File "/usr/local/lib/python3.4/dist-packages/django/__init__.py", line 21, in setup
    apps.populate(settings.INSTALLED_APPS)
  File "/usr/local/lib/python3.4/dist-packages/django/apps/registry.py", line 108, in populate
    app_config.import_models(all_models)
  File "/usr/local/lib/python3.4/dist-packages/django/apps/config.py", line 202, in import_models
    self.models_module = import_module(models_module_name)
  File "/usr/lib/python3.4/importlib/__init__.py", line 109, in import_module
    return _bootstrap._gcd_import(name[level:], package, level)
  File "/var/www/compagnieinterface/spectacles_lieux_bdd/models.py", line 243, in <module>
    class EventsGroup(models.Model):
  File "/usr/local/lib/python3.4/dist-packages/django/db/models/base.py", line 170, in __new__
    new_class.add_to_class(obj_name, obj)
  File "/usr/local/lib/python3.4/dist-packages/django/db/models/base.py", line 299, in add_to_class
    value.contribute_to_class(cls, name)
TypeError: contribute_to_class() missing 1 required positional argument: 'name'
Traceback (most recent call last):
  File "/usr/local/lib/python3.4/dist-packages/gunicorn/arbiter.py", line 507, in spawn_worker
    worker.init_process()
  File "/usr/local/lib/python3.4/dist-packages/gunicorn/workers/base.py", line 114, in init_process
    self.wsgi = self.app.wsgi()
  File "/usr/local/lib/python3.4/dist-packages/gunicorn/app/base.py", line 66, in wsgi
    self.callable = self.load()
  File "/usr/local/lib/python3.4/dist-packages/gunicorn/app/wsgiapp.py", line 65, in load
    return self.load_wsgiapp()
  File "/usr/local/lib/python3.4/dist-packages/gunicorn/app/wsgiapp.py", line 52, in load_wsgiapp
    return util.import_app(self.app_uri)
  File "/usr/local/lib/python3.4/dist-packages/gunicorn/util.py", line 356, in import_app
    __import__(module)
  File "/var/www/compagnieinterface/sandbox/wsgi.py", line 16, in <module>
    application = get_wsgi_application()
  File "/usr/local/lib/python3.4/dist-packages/django/core/wsgi.py", line 14, in get_wsgi_application
    django.setup()
  File "/usr/local/lib/python3.4/dist-packages/django/__init__.py", line 21, in setup
    apps.populate(settings.INSTALLED_APPS)
  File "/usr/local/lib/python3.4/dist-packages/django/apps/registry.py", line 108, in populate
    app_config.import_models(all_models)
  File "/usr/local/lib/python3.4/dist-packages/django/apps/config.py", line 202, in import_models
    self.models_module = import_module(models_module_name)
  File "/usr/lib/python3.4/importlib/__init__.py", line 109, in import_module
    return _bootstrap._gcd_import(name[level:], package, level)
  File "/var/www/compagnieinterface/spectacles_lieux_bdd/models.py", line 243, in <module>
    class EventsGroup(models.Model):
  File "/usr/local/lib/python3.4/dist-packages/django/db/models/base.py", line 170, in __new__
    new_class.add_to_class(obj_name, obj)
  File "/usr/local/lib/python3.4/dist-packages/django/db/models/base.py", line 299, in add_to_class
    value.contribute_to_class(cls, name)
TypeError: contribute_to_class() missing 1 required positional argument: 'name'
Exception in worker process:
Traceback (most recent call last):
  File "/usr/local/lib/python3.4/dist-packages/gunicorn/arbiter.py", line 507, in spawn_worker
    worker.init_process()
  File "/usr/local/lib/python3.4/dist-packages/gunicorn/workers/base.py", line 114, in init_process
    self.wsgi = self.app.wsgi()
  File "/usr/local/lib/python3.4/dist-packages/gunicorn/app/base.py", line 66, in wsgi
    self.callable = self.load()
  File "/usr/local/lib/python3.4/dist-packages/gunicorn/app/wsgiapp.py", line 65, in load
    return self.load_wsgiapp()
  File "/usr/local/lib/python3.4/dist-packages/gunicorn/app/wsgiapp.py", line 52, in load_wsgiapp
    return util.import_app(self.app_uri)
  File "/usr/local/lib/python3.4/dist-packages/gunicorn/util.py", line 356, in import_app
    __import__(module)
  File "/var/www/compagnieinterface/sandbox/wsgi.py", line 16, in <module>
    application = get_wsgi_application()
  File "/usr/local/lib/python3.4/dist-packages/django/core/wsgi.py", line 14, in get_wsgi_application
    django.setup()
  File "/usr/local/lib/python3.4/dist-packages/django/__init__.py", line 21, in setup
    apps.populate(settings.INSTALLED_APPS)
  File "/usr/local/lib/python3.4/dist-packages/django/apps/registry.py", line 108, in populate
    app_config.import_models(all_models)
  File "/usr/local/lib/python3.4/dist-packages/django/apps/config.py", line 202, in import_models
    self.models_module = import_module(models_module_name)
  File "/usr/lib/python3.4/importlib/__init__.py", line 109, in import_module
    return _bootstrap._gcd_import(name[level:], package, level)
  File "/var/www/compagnieinterface/spectacles_lieux_bdd/models.py", line 243, in <module>
    class EventsGroup(models.Model):
  File "/usr/local/lib/python3.4/dist-packages/django/db/models/base.py", line 170, in __new__
    new_class.add_to_class(obj_name, obj)
  File "/usr/local/lib/python3.4/dist-packages/django/db/models/base.py", line 299, in add_to_class
    value.contribute_to_class(cls, name)
TypeError: contribute_to_class() missing 1 required positional argument: 'name'
Traceback (most recent call last):
  File "/usr/local/lib/python3.4/dist-packages/gunicorn/arbiter.py", line 507, in spawn_worker
    worker.init_process()
  File "/usr/local/lib/python3.4/dist-packages/gunicorn/workers/base.py", line 114, in init_process
    self.wsgi = self.app.wsgi()
  File "/usr/local/lib/python3.4/dist-packages/gunicorn/app/base.py", line 66, in wsgi
    self.callable = self.load()
  File "/usr/local/lib/python3.4/dist-packages/gunicorn/app/wsgiapp.py", line 65, in load
    return self.load_wsgiapp()
  File "/usr/local/lib/python3.4/dist-packages/gunicorn/app/wsgiapp.py", line 52, in load_wsgiapp
    return util.import_app(self.app_uri)
  File "/usr/local/lib/python3.4/dist-packages/gunicorn/util.py", line 356, in import_app
    __import__(module)
  File "/var/www/compagnieinterface/sandbox/wsgi.py", line 16, in <module>
    application = get_wsgi_application()
  File "/usr/local/lib/python3.4/dist-packages/django/core/wsgi.py", line 14, in get_wsgi_application
    django.setup()
  File "/usr/local/lib/python3.4/dist-packages/django/__init__.py", line 21, in setup
    apps.populate(settings.INSTALLED_APPS)
  File "/usr/local/lib/python3.4/dist-packages/django/apps/registry.py", line 108, in populate
    app_config.import_models(all_models)
  File "/usr/local/lib/python3.4/dist-packages/django/apps/config.py", line 202, in import_models
    self.models_module = import_module(models_module_name)
  File "/usr/lib/python3.4/importlib/__init__.py", line 109, in import_module
    return _bootstrap._gcd_import(name[level:], package, level)
  File "/var/www/compagnieinterface/spectacles_lieux_bdd/models.py", line 243, in <module>
    class EventsGroup(models.Model):
  File "/usr/local/lib/python3.4/dist-packages/django/db/models/base.py", line 170, in __new__
    new_class.add_to_class(obj_name, obj)
  File "/usr/local/lib/python3.4/dist-packages/django/db/models/base.py", line 299, in add_to_class
    value.contribute_to_class(cls, name)
TypeError: contribute_to_class() missing 1 required positional argument: 'name'
[2016-01-14 10:44:18 -0500] [8448] [INFO] Starting gunicorn 19.3.0
[2016-01-14 10:44:18 -0500] [8448] [INFO] Listening at: http://127.0.0.1:8005 (8448)
[2016-01-14 10:44:18 -0500] [8448] [INFO] Using worker: sync
[2016-01-14 10:44:18 -0500] [8453] [INFO] Booting worker with pid: 8453
[2016-01-14 10:44:18 -0500] [8454] [INFO] Booting worker with pid: 8454
[2016-01-14 10:44:18 -0500] [8455] [INFO] Booting worker with pid: 8455
[2016-01-14 10:51:58 -0500] [8448] [INFO] Handling signal: term
[2016-01-14 15:51:58 +0000] [8453] [INFO] Worker exiting (pid: 8453)
[2016-01-14 15:51:58 +0000] [8454] [INFO] Worker exiting (pid: 8454)
[2016-01-14 15:51:58 +0000] [8455] [INFO] Worker exiting (pid: 8455)
[2016-01-14 10:51:59 -0500] [8448] [INFO] Shutting down: Master
[2016-01-14 10:52:01 -0500] [8715] [INFO] Starting gunicorn 19.3.0
[2016-01-14 10:52:01 -0500] [8715] [INFO] Listening at: http://127.0.0.1:8005 (8715)
[2016-01-14 10:52:01 -0500] [8715] [INFO] Using worker: sync
[2016-01-14 10:52:01 -0500] [8720] [INFO] Booting worker with pid: 8720
[2016-01-14 10:52:01 -0500] [8721] [INFO] Booting worker with pid: 8721
[2016-01-14 10:52:01 -0500] [8722] [INFO] Booting worker with pid: 8722
[2016-01-16 09:56:51 -0500] [8715] [INFO] Handling signal: term
[2016-01-16 14:56:51 +0000] [8722] [INFO] Worker exiting (pid: 8722)
[2016-01-16 14:56:51 +0000] [8721] [INFO] Worker exiting (pid: 8721)
[2016-01-16 14:56:51 +0000] [8720] [INFO] Worker exiting (pid: 8720)
[2016-01-16 09:56:52 -0500] [8715] [INFO] Shutting down: Master
[2016-01-16 09:56:54 -0500] [9243] [INFO] Starting gunicorn 19.3.0
[2016-01-16 09:56:54 -0500] [9243] [INFO] Listening at: http://127.0.0.1:8005 (9243)
[2016-01-16 09:56:54 -0500] [9243] [INFO] Using worker: sync
[2016-01-16 09:56:54 -0500] [9248] [INFO] Booting worker with pid: 9248
[2016-01-16 09:56:54 -0500] [9249] [INFO] Booting worker with pid: 9249
[2016-01-16 09:56:54 -0500] [9250] [INFO] Booting worker with pid: 9250
[2016-01-16 09:56:55 -0500] [9248] [ERROR] Exception in worker process:
Traceback (most recent call last):
  File "/root/.virtualenvs/compagnieinterface/lib/python3.4/site-packages/gunicorn/arbiter.py", line 507, in spawn_worker
    worker.init_process()
  File "/root/.virtualenvs/compagnieinterface/lib/python3.4/site-packages/gunicorn/workers/base.py", line 118, in init_process
    self.wsgi = self.app.wsgi()
  File "/root/.virtualenvs/compagnieinterface/lib/python3.4/site-packages/gunicorn/app/base.py", line 67, in wsgi
    self.callable = self.load()
  File "/root/.virtualenvs/compagnieinterface/lib/python3.4/site-packages/gunicorn/app/wsgiapp.py", line 65, in load
    return self.load_wsgiapp()
  File "/root/.virtualenvs/compagnieinterface/lib/python3.4/site-packages/gunicorn/app/wsgiapp.py", line 52, in load_wsgiapp
    return util.import_app(self.app_uri)
  File "/root/.virtualenvs/compagnieinterface/lib/python3.4/site-packages/gunicorn/util.py", line 355, in import_app
    __import__(module)
  File "/var/www/compagnieinterface/sandbox/wsgi.py", line 16, in <module>
    application = get_wsgi_application()
  File "/root/.virtualenvs/compagnieinterface/lib/python3.4/site-packages/django/core/wsgi.py", line 14, in get_wsgi_application
    django.setup()
  File "/root/.virtualenvs/compagnieinterface/lib/python3.4/site-packages/django/__init__.py", line 17, in setup
    configure_logging(settings.LOGGING_CONFIG, settings.LOGGING)
  File "/root/.virtualenvs/compagnieinterface/lib/python3.4/site-packages/django/conf/__init__.py", line 48, in __getattr__
    self._setup(name)
  File "/root/.virtualenvs/compagnieinterface/lib/python3.4/site-packages/django/conf/__init__.py", line 44, in _setup
    self._wrapped = Settings(settings_module)
  File "/root/.virtualenvs/compagnieinterface/lib/python3.4/site-packages/django/conf/__init__.py", line 92, in __init__
    mod = importlib.import_module(self.SETTINGS_MODULE)
  File "/root/.virtualenvs/compagnieinterface/lib/python3.4/importlib/__init__.py", line 109, in import_module
    return _bootstrap._gcd_import(name[level:], package, level)
  File "/var/www/compagnieinterface/sandbox/settings.py", line 144
    ]
    ^
SyntaxError: invalid syntax
Traceback (most recent call last):
  File "/root/.virtualenvs/compagnieinterface/lib/python3.4/site-packages/gunicorn/arbiter.py", line 507, in spawn_worker
    worker.init_process()
  File "/root/.virtualenvs/compagnieinterface/lib/python3.4/site-packages/gunicorn/workers/base.py", line 118, in init_process
    self.wsgi = self.app.wsgi()
  File "/root/.virtualenvs/compagnieinterface/lib/python3.4/site-packages/gunicorn/app/base.py", line 67, in wsgi
    self.callable = self.load()
  File "/root/.virtualenvs/compagnieinterface/lib/python3.4/site-packages/gunicorn/app/wsgiapp.py", line 65, in load
    return self.load_wsgiapp()
  File "/root/.virtualenvs/compagnieinterface/lib/python3.4/site-packages/gunicorn/app/wsgiapp.py", line 52, in load_wsgiapp
    return util.import_app(self.app_uri)
  File "/root/.virtualenvs/compagnieinterface/lib/python3.4/site-packages/gunicorn/util.py", line 355, in import_app
    __import__(module)
  File "/var/www/compagnieinterface/sandbox/wsgi.py", line 16, in <module>
    application = get_wsgi_application()
  File "/root/.virtualenvs/compagnieinterface/lib/python3.4/site-packages/django/core/wsgi.py", line 14, in get_wsgi_application
    django.setup()
  File "/root/.virtualenvs/compagnieinterface/lib/python3.4/site-packages/django/__init__.py", line 17, in setup
    configure_logging(settings.LOGGING_CONFIG, settings.LOGGING)
  File "/root/.virtualenvs/compagnieinterface/lib/python3.4/site-packages/django/conf/__init__.py", line 48, in __getattr__
    self._setup(name)
  File "/root/.virtualenvs/compagnieinterface/lib/python3.4/site-packages/django/conf/__init__.py", line 44, in _setup
    self._wrapped = Settings(settings_module)
  File "/root/.virtualenvs/compagnieinterface/lib/python3.4/site-packages/django/conf/__init__.py", line 92, in __init__
    mod = importlib.import_module(self.SETTINGS_MODULE)
  File "/root/.virtualenvs/compagnieinterface/lib/python3.4/importlib/__init__.py", line 109, in import_module
    return _bootstrap._gcd_import(name[level:], package, level)
  File "/var/www/compagnieinterface/sandbox/settings.py", line 144
    ]
    ^
SyntaxError: invalid syntax
[2016-01-16 09:56:55 -0500] [9249] [ERROR] Exception in worker process:
Traceback (most recent call last):
  File "/root/.virtualenvs/compagnieinterface/lib/python3.4/site-packages/gunicorn/arbiter.py", line 507, in spawn_worker
    worker.init_process()
  File "/root/.virtualenvs/compagnieinterface/lib/python3.4/site-packages/gunicorn/workers/base.py", line 118, in init_process
    self.wsgi = self.app.wsgi()
  File "/root/.virtualenvs/compagnieinterface/lib/python3.4/site-packages/gunicorn/app/base.py", line 67, in wsgi
    self.callable = self.load()
  File "/root/.virtualenvs/compagnieinterface/lib/python3.4/site-packages/gunicorn/app/wsgiapp.py", line 65, in load
    return self.load_wsgiapp()
  File "/root/.virtualenvs/compagnieinterface/lib/python3.4/site-packages/gunicorn/app/wsgiapp.py", line 52, in load_wsgiapp
    return util.import_app(self.app_uri)
  File "/root/.virtualenvs/compagnieinterface/lib/python3.4/site-packages/gunicorn/util.py", line 355, in import_app
    __import__(module)
  File "/var/www/compagnieinterface/sandbox/wsgi.py", line 16, in <module>
    application = get_wsgi_application()
  File "/root/.virtualenvs/compagnieinterface/lib/python3.4/site-packages/django/core/wsgi.py", line 14, in get_wsgi_application
    django.setup()
  File "/root/.virtualenvs/compagnieinterface/lib/python3.4/site-packages/django/__init__.py", line 17, in setup
    configure_logging(settings.LOGGING_CONFIG, settings.LOGGING)
  File "/root/.virtualenvs/compagnieinterface/lib/python3.4/site-packages/django/conf/__init__.py", line 48, in __getattr__
    self._setup(name)
  File "/root/.virtualenvs/compagnieinterface/lib/python3.4/site-packages/django/conf/__init__.py", line 44, in _setup
    self._wrapped = Settings(settings_module)
  File "/root/.virtualenvs/compagnieinterface/lib/python3.4/site-packages/django/conf/__init__.py", line 92, in __init__
    mod = importlib.import_module(self.SETTINGS_MODULE)
  File "/root/.virtualenvs/compagnieinterface/lib/python3.4/importlib/__init__.py", line 109, in import_module
    return _bootstrap._gcd_import(name[level:], package, level)
  File "/var/www/compagnieinterface/sandbox/settings.py", line 144
    ]
    ^
SyntaxError: invalid syntax
Traceback (most recent call last):
  File "/root/.virtualenvs/compagnieinterface/lib/python3.4/site-packages/gunicorn/arbiter.py", line 507, in spawn_worker
    worker.init_process()
  File "/root/.virtualenvs/compagnieinterface/lib/python3.4/site-packages/gunicorn/workers/base.py", line 118, in init_process
    self.wsgi = self.app.wsgi()
  File "/root/.virtualenvs/compagnieinterface/lib/python3.4/site-packages/gunicorn/app/base.py", line 67, in wsgi
    self.callable = self.load()
  File "/root/.virtualenvs/compagnieinterface/lib/python3.4/site-packages/gunicorn/app/wsgiapp.py", line 65, in load
    return self.load_wsgiapp()
  File "/root/.virtualenvs/compagnieinterface/lib/python3.4/site-packages/gunicorn/app/wsgiapp.py", line 52, in load_wsgiapp
    return util.import_app(self.app_uri)
  File "/root/.virtualenvs/compagnieinterface/lib/python3.4/site-packages/gunicorn/util.py", line 355, in import_app
    __import__(module)
  File "/var/www/compagnieinterface/sandbox/wsgi.py", line 16, in <module>
    application = get_wsgi_application()
  File "/root/.virtualenvs/compagnieinterface/lib/python3.4/site-packages/django/core/wsgi.py", line 14, in get_wsgi_application
    django.setup()
  File "/root/.virtualenvs/compagnieinterface/lib/python3.4/site-packages/django/__init__.py", line 17, in setup
    configure_logging(settings.LOGGING_CONFIG, settings.LOGGING)
  File "/root/.virtualenvs/compagnieinterface/lib/python3.4/site-packages/django/conf/__init__.py", line 48, in __getattr__
    self._setup(name)
  File "/root/.virtualenvs/compagnieinterface/lib/python3.4/site-packages/django/conf/__init__.py", line 44, in _setup
    self._wrapped = Settings(settings_module)
  File "/root/.virtualenvs/compagnieinterface/lib/python3.4/site-packages/django/conf/__init__.py", line 92, in __init__
    mod = importlib.import_module(self.SETTINGS_MODULE)
  File "/root/.virtualenvs/compagnieinterface/lib/python3.4/importlib/__init__.py", line 109, in import_module
    return _bootstrap._gcd_import(name[level:], package, level)
  File "/var/www/compagnieinterface/sandbox/settings.py", line 144
    ]
    ^
SyntaxError: invalid syntax
[2016-01-16 09:56:55 -0500] [9249] [INFO] Worker exiting (pid: 9249)
[2016-01-16 09:56:55 -0500] [9248] [INFO] Worker exiting (pid: 9248)
[2016-01-16 09:56:55 -0500] [9250] [ERROR] Exception in worker process:
Traceback (most recent call last):
  File "/root/.virtualenvs/compagnieinterface/lib/python3.4/site-packages/gunicorn/arbiter.py", line 507, in spawn_worker
    worker.init_process()
  File "/root/.virtualenvs/compagnieinterface/lib/python3.4/site-packages/gunicorn/workers/base.py", line 118, in init_process
    self.wsgi = self.app.wsgi()
  File "/root/.virtualenvs/compagnieinterface/lib/python3.4/site-packages/gunicorn/app/base.py", line 67, in wsgi
    self.callable = self.load()
  File "/root/.virtualenvs/compagnieinterface/lib/python3.4/site-packages/gunicorn/app/wsgiapp.py", line 65, in load
    return self.load_wsgiapp()
  File "/root/.virtualenvs/compagnieinterface/lib/python3.4/site-packages/gunicorn/app/wsgiapp.py", line 52, in load_wsgiapp
    return util.import_app(self.app_uri)
  File "/root/.virtualenvs/compagnieinterface/lib/python3.4/site-packages/gunicorn/util.py", line 355, in import_app
    __import__(module)
  File "/var/www/compagnieinterface/sandbox/wsgi.py", line 16, in <module>
    application = get_wsgi_application()
  File "/root/.virtualenvs/compagnieinterface/lib/python3.4/site-packages/django/core/wsgi.py", line 14, in get_wsgi_application
    django.setup()
  File "/root/.virtualenvs/compagnieinterface/lib/python3.4/site-packages/django/__init__.py", line 17, in setup
    configure_logging(settings.LOGGING_CONFIG, settings.LOGGING)
  File "/root/.virtualenvs/compagnieinterface/lib/python3.4/site-packages/django/conf/__init__.py", line 48, in __getattr__
    self._setup(name)
  File "/root/.virtualenvs/compagnieinterface/lib/python3.4/site-packages/django/conf/__init__.py", line 44, in _setup
    self._wrapped = Settings(settings_module)
  File "/root/.virtualenvs/compagnieinterface/lib/python3.4/site-packages/django/conf/__init__.py", line 92, in __init__
    mod = importlib.import_module(self.SETTINGS_MODULE)
  File "/root/.virtualenvs/compagnieinterface/lib/python3.4/importlib/__init__.py", line 109, in import_module
    return _bootstrap._gcd_import(name[level:], package, level)
  File "/var/www/compagnieinterface/sandbox/settings.py", line 144
    ]
    ^
SyntaxError: invalid syntax
Traceback (most recent call last):
  File "/root/.virtualenvs/compagnieinterface/lib/python3.4/site-packages/gunicorn/arbiter.py", line 507, in spawn_worker
    worker.init_process()
  File "/root/.virtualenvs/compagnieinterface/lib/python3.4/site-packages/gunicorn/workers/base.py", line 118, in init_process
    self.wsgi = self.app.wsgi()
  File "/root/.virtualenvs/compagnieinterface/lib/python3.4/site-packages/gunicorn/app/base.py", line 67, in wsgi
    self.callable = self.load()
  File "/root/.virtualenvs/compagnieinterface/lib/python3.4/site-packages/gunicorn/app/wsgiapp.py", line 65, in load
    return self.load_wsgiapp()
  File "/root/.virtualenvs/compagnieinterface/lib/python3.4/site-packages/gunicorn/app/wsgiapp.py", line 52, in load_wsgiapp
    return util.import_app(self.app_uri)
  File "/root/.virtualenvs/compagnieinterface/lib/python3.4/site-packages/gunicorn/util.py", line 355, in import_app
    __import__(module)
  File "/var/www/compagnieinterface/sandbox/wsgi.py", line 16, in <module>
    application = get_wsgi_application()
  File "/root/.virtualenvs/compagnieinterface/lib/python3.4/site-packages/django/core/wsgi.py", line 14, in get_wsgi_application
    django.setup()
  File "/root/.virtualenvs/compagnieinterface/lib/python3.4/site-packages/django/__init__.py", line 17, in setup
    configure_logging(settings.LOGGING_CONFIG, settings.LOGGING)
  File "/root/.virtualenvs/compagnieinterface/lib/python3.4/site-packages/django/conf/__init__.py", line 48, in __getattr__
    self._setup(name)
  File "/root/.virtualenvs/compagnieinterface/lib/python3.4/site-packages/django/conf/__init__.py", line 44, in _setup
    self._wrapped = Settings(settings_module)
  File "/root/.virtualenvs/compagnieinterface/lib/python3.4/site-packages/django/conf/__init__.py", line 92, in __init__
    mod = importlib.import_module(self.SETTINGS_MODULE)
  File "/root/.virtualenvs/compagnieinterface/lib/python3.4/importlib/__init__.py", line 109, in import_module
    return _bootstrap._gcd_import(name[level:], package, level)
  File "/var/www/compagnieinterface/sandbox/settings.py", line 144
    ]
    ^
SyntaxError: invalid syntax
[2016-01-16 09:56:55 -0500] [9250] [INFO] Worker exiting (pid: 9250)
[2016-01-16 09:56:55 -0500] [9243] [INFO] Shutting down: Master
[2016-01-16 09:56:55 -0500] [9243] [INFO] Reason: Worker failed to boot.
[2016-01-16 09:57:13 -0500] [9261] [INFO] Starting gunicorn 19.3.0
[2016-01-16 09:57:13 -0500] [9261] [INFO] Listening at: http://127.0.0.1:8005 (9261)
[2016-01-16 09:57:13 -0500] [9261] [INFO] Using worker: sync
[2016-01-16 09:57:13 -0500] [9266] [INFO] Booting worker with pid: 9266
[2016-01-16 09:57:14 -0500] [9267] [INFO] Booting worker with pid: 9267
[2016-01-16 09:57:14 -0500] [9269] [INFO] Booting worker with pid: 9269
[2016-01-16 09:57:14 -0500] [9266] [ERROR] Exception in worker process:
Traceback (most recent call last):
  File "/root/.virtualenvs/compagnieinterface/lib/python3.4/site-packages/gunicorn/arbiter.py", line 507, in spawn_worker
    worker.init_process()
  File "/root/.virtualenvs/compagnieinterface/lib/python3.4/site-packages/gunicorn/workers/base.py", line 118, in init_process
    self.wsgi = self.app.wsgi()
  File "/root/.virtualenvs/compagnieinterface/lib/python3.4/site-packages/gunicorn/app/base.py", line 67, in wsgi
    self.callable = self.load()
  File "/root/.virtualenvs/compagnieinterface/lib/python3.4/site-packages/gunicorn/app/wsgiapp.py", line 65, in load
    return self.load_wsgiapp()
  File "/root/.virtualenvs/compagnieinterface/lib/python3.4/site-packages/gunicorn/app/wsgiapp.py", line 52, in load_wsgiapp
    return util.import_app(self.app_uri)
  File "/root/.virtualenvs/compagnieinterface/lib/python3.4/site-packages/gunicorn/util.py", line 355, in import_app
    __import__(module)
  File "/var/www/compagnieinterface/sandbox/wsgi.py", line 16, in <module>
    application = get_wsgi_application()
  File "/root/.virtualenvs/compagnieinterface/lib/python3.4/site-packages/django/core/wsgi.py", line 14, in get_wsgi_application
    django.setup()
  File "/root/.virtualenvs/compagnieinterface/lib/python3.4/site-packages/django/__init__.py", line 17, in setup
    configure_logging(settings.LOGGING_CONFIG, settings.LOGGING)
  File "/root/.virtualenvs/compagnieinterface/lib/python3.4/site-packages/django/conf/__init__.py", line 48, in __getattr__
    self._setup(name)
  File "/root/.virtualenvs/compagnieinterface/lib/python3.4/site-packages/django/conf/__init__.py", line 44, in _setup
    self._wrapped = Settings(settings_module)
  File "/root/.virtualenvs/compagnieinterface/lib/python3.4/site-packages/django/conf/__init__.py", line 92, in __init__
    mod = importlib.import_module(self.SETTINGS_MODULE)
  File "/root/.virtualenvs/compagnieinterface/lib/python3.4/importlib/__init__.py", line 109, in import_module
    return _bootstrap._gcd_import(name[level:], package, level)
  File "/var/www/compagnieinterface/sandbox/settings.py", line 144
    ]
    ^
SyntaxError: invalid syntax
Traceback (most recent call last):
  File "/root/.virtualenvs/compagnieinterface/lib/python3.4/site-packages/gunicorn/arbiter.py", line 507, in spawn_worker
    worker.init_process()
  File "/root/.virtualenvs/compagnieinterface/lib/python3.4/site-packages/gunicorn/workers/base.py", line 118, in init_process
    self.wsgi = self.app.wsgi()
  File "/root/.virtualenvs/compagnieinterface/lib/python3.4/site-packages/gunicorn/app/base.py", line 67, in wsgi
    self.callable = self.load()
  File "/root/.virtualenvs/compagnieinterface/lib/python3.4/site-packages/gunicorn/app/wsgiapp.py", line 65, in load
    return self.load_wsgiapp()
  File "/root/.virtualenvs/compagnieinterface/lib/python3.4/site-packages/gunicorn/app/wsgiapp.py", line 52, in load_wsgiapp
    return util.import_app(self.app_uri)
  File "/root/.virtualenvs/compagnieinterface/lib/python3.4/site-packages/gunicorn/util.py", line 355, in import_app
    __import__(module)
  File "/var/www/compagnieinterface/sandbox/wsgi.py", line 16, in <module>
    application = get_wsgi_application()
  File "/root/.virtualenvs/compagnieinterface/lib/python3.4/site-packages/django/core/wsgi.py", line 14, in get_wsgi_application
    django.setup()
  File "/root/.virtualenvs/compagnieinterface/lib/python3.4/site-packages/django/__init__.py", line 17, in setup
    configure_logging(settings.LOGGING_CONFIG, settings.LOGGING)
  File "/root/.virtualenvs/compagnieinterface/lib/python3.4/site-packages/django/conf/__init__.py", line 48, in __getattr__
    self._setup(name)
  File "/root/.virtualenvs/compagnieinterface/lib/python3.4/site-packages/django/conf/__init__.py", line 44, in _setup
    self._wrapped = Settings(settings_module)
  File "/root/.virtualenvs/compagnieinterface/lib/python3.4/site-packages/django/conf/__init__.py", line 92, in __init__
    mod = importlib.import_module(self.SETTINGS_MODULE)
  File "/root/.virtualenvs/compagnieinterface/lib/python3.4/importlib/__init__.py", line 109, in import_module
    return _bootstrap._gcd_import(name[level:], package, level)
  File "/var/www/compagnieinterface/sandbox/settings.py", line 144
    ]
    ^
SyntaxError: invalid syntax
[2016-01-16 09:57:14 -0500] [9266] [INFO] Worker exiting (pid: 9266)
[2016-01-16 09:57:14 -0500] [9267] [ERROR] Exception in worker process:
Traceback (most recent call last):
  File "/root/.virtualenvs/compagnieinterface/lib/python3.4/site-packages/gunicorn/arbiter.py", line 507, in spawn_worker
    worker.init_process()
  File "/root/.virtualenvs/compagnieinterface/lib/python3.4/site-packages/gunicorn/workers/base.py", line 118, in init_process
    self.wsgi = self.app.wsgi()
  File "/root/.virtualenvs/compagnieinterface/lib/python3.4/site-packages/gunicorn/app/base.py", line 67, in wsgi
    self.callable = self.load()
  File "/root/.virtualenvs/compagnieinterface/lib/python3.4/site-packages/gunicorn/app/wsgiapp.py", line 65, in load
    return self.load_wsgiapp()
  File "/root/.virtualenvs/compagnieinterface/lib/python3.4/site-packages/gunicorn/app/wsgiapp.py", line 52, in load_wsgiapp
    return util.import_app(self.app_uri)
  File "/root/.virtualenvs/compagnieinterface/lib/python3.4/site-packages/gunicorn/util.py", line 355, in import_app
    __import__(module)
  File "/var/www/compagnieinterface/sandbox/wsgi.py", line 16, in <module>
    application = get_wsgi_application()
  File "/root/.virtualenvs/compagnieinterface/lib/python3.4/site-packages/django/core/wsgi.py", line 14, in get_wsgi_application
    django.setup()
  File "/root/.virtualenvs/compagnieinterface/lib/python3.4/site-packages/django/__init__.py", line 17, in setup
    configure_logging(settings.LOGGING_CONFIG, settings.LOGGING)
  File "/root/.virtualenvs/compagnieinterface/lib/python3.4/site-packages/django/conf/__init__.py", line 48, in __getattr__
    self._setup(name)
  File "/root/.virtualenvs/compagnieinterface/lib/python3.4/site-packages/django/conf/__init__.py", line 44, in _setup
    self._wrapped = Settings(settings_module)
  File "/root/.virtualenvs/compagnieinterface/lib/python3.4/site-packages/django/conf/__init__.py", line 92, in __init__
    mod = importlib.import_module(self.SETTINGS_MODULE)
  File "/root/.virtualenvs/compagnieinterface/lib/python3.4/importlib/__init__.py", line 109, in import_module
    return _bootstrap._gcd_import(name[level:], package, level)
  File "/var/www/compagnieinterface/sandbox/settings.py", line 144
    ]
    ^
SyntaxError: invalid syntax
Traceback (most recent call last):
  File "/root/.virtualenvs/compagnieinterface/lib/python3.4/site-packages/gunicorn/arbiter.py", line 507, in spawn_worker
    worker.init_process()
  File "/root/.virtualenvs/compagnieinterface/lib/python3.4/site-packages/gunicorn/workers/base.py", line 118, in init_process
    self.wsgi = self.app.wsgi()
  File "/root/.virtualenvs/compagnieinterface/lib/python3.4/site-packages/gunicorn/app/base.py", line 67, in wsgi
    self.callable = self.load()
  File "/root/.virtualenvs/compagnieinterface/lib/python3.4/site-packages/gunicorn/app/wsgiapp.py", line 65, in load
    return self.load_wsgiapp()
  File "/root/.virtualenvs/compagnieinterface/lib/python3.4/site-packages/gunicorn/app/wsgiapp.py", line 52, in load_wsgiapp
    return util.import_app(self.app_uri)
  File "/root/.virtualenvs/compagnieinterface/lib/python3.4/site-packages/gunicorn/util.py", line 355, in import_app
    __import__(module)
  File "/var/www/compagnieinterface/sandbox/wsgi.py", line 16, in <module>
    application = get_wsgi_application()
  File "/root/.virtualenvs/compagnieinterface/lib/python3.4/site-packages/django/core/wsgi.py", line 14, in get_wsgi_application
    django.setup()
  File "/root/.virtualenvs/compagnieinterface/lib/python3.4/site-packages/django/__init__.py", line 17, in setup
    configure_logging(settings.LOGGING_CONFIG, settings.LOGGING)
  File "/root/.virtualenvs/compagnieinterface/lib/python3.4/site-packages/django/conf/__init__.py", line 48, in __getattr__
    self._setup(name)
  File "/root/.virtualenvs/compagnieinterface/lib/python3.4/site-packages/django/conf/__init__.py", line 44, in _setup
    self._wrapped = Settings(settings_module)
  File "/root/.virtualenvs/compagnieinterface/lib/python3.4/site-packages/django/conf/__init__.py", line 92, in __init__
    mod = importlib.import_module(self.SETTINGS_MODULE)
  File "/root/.virtualenvs/compagnieinterface/lib/python3.4/importlib/__init__.py", line 109, in import_module
    return _bootstrap._gcd_import(name[level:], package, level)
  File "/var/www/compagnieinterface/sandbox/settings.py", line 144
    ]
    ^
SyntaxError: invalid syntax
[2016-01-16 09:57:14 -0500] [9267] [INFO] Worker exiting (pid: 9267)
[2016-01-16 09:57:14 -0500] [9269] [ERROR] Exception in worker process:
Traceback (most recent call last):
  File "/root/.virtualenvs/compagnieinterface/lib/python3.4/site-packages/gunicorn/arbiter.py", line 507, in spawn_worker
    worker.init_process()
  File "/root/.virtualenvs/compagnieinterface/lib/python3.4/site-packages/gunicorn/workers/base.py", line 118, in init_process
    self.wsgi = self.app.wsgi()
  File "/root/.virtualenvs/compagnieinterface/lib/python3.4/site-packages/gunicorn/app/base.py", line 67, in wsgi
    self.callable = self.load()
  File "/root/.virtualenvs/compagnieinterface/lib/python3.4/site-packages/gunicorn/app/wsgiapp.py", line 65, in load
    return self.load_wsgiapp()
  File "/root/.virtualenvs/compagnieinterface/lib/python3.4/site-packages/gunicorn/app/wsgiapp.py", line 52, in load_wsgiapp
    return util.import_app(self.app_uri)
  File "/root/.virtualenvs/compagnieinterface/lib/python3.4/site-packages/gunicorn/util.py", line 355, in import_app
    __import__(module)
  File "/var/www/compagnieinterface/sandbox/wsgi.py", line 16, in <module>
    application = get_wsgi_application()
  File "/root/.virtualenvs/compagnieinterface/lib/python3.4/site-packages/django/core/wsgi.py", line 14, in get_wsgi_application
    django.setup()
  File "/root/.virtualenvs/compagnieinterface/lib/python3.4/site-packages/django/__init__.py", line 17, in setup
    configure_logging(settings.LOGGING_CONFIG, settings.LOGGING)
  File "/root/.virtualenvs/compagnieinterface/lib/python3.4/site-packages/django/conf/__init__.py", line 48, in __getattr__
    self._setup(name)
  File "/root/.virtualenvs/compagnieinterface/lib/python3.4/site-packages/django/conf/__init__.py", line 44, in _setup
    self._wrapped = Settings(settings_module)
  File "/root/.virtualenvs/compagnieinterface/lib/python3.4/site-packages/django/conf/__init__.py", line 92, in __init__
    mod = importlib.import_module(self.SETTINGS_MODULE)
  File "/root/.virtualenvs/compagnieinterface/lib/python3.4/importlib/__init__.py", line 109, in import_module
    return _bootstrap._gcd_import(name[level:], package, level)
  File "/var/www/compagnieinterface/sandbox/settings.py", line 144
    ]
    ^
SyntaxError: invalid syntax
Traceback (most recent call last):
  File "/root/.virtualenvs/compagnieinterface/lib/python3.4/site-packages/gunicorn/arbiter.py", line 507, in spawn_worker
    worker.init_process()
  File "/root/.virtualenvs/compagnieinterface/lib/python3.4/site-packages/gunicorn/workers/base.py", line 118, in init_process
    self.wsgi = self.app.wsgi()
  File "/root/.virtualenvs/compagnieinterface/lib/python3.4/site-packages/gunicorn/app/base.py", line 67, in wsgi
    self.callable = self.load()
  File "/root/.virtualenvs/compagnieinterface/lib/python3.4/site-packages/gunicorn/app/wsgiapp.py", line 65, in load
    return self.load_wsgiapp()
  File "/root/.virtualenvs/compagnieinterface/lib/python3.4/site-packages/gunicorn/app/wsgiapp.py", line 52, in load_wsgiapp
    return util.import_app(self.app_uri)
  File "/root/.virtualenvs/compagnieinterface/lib/python3.4/site-packages/gunicorn/util.py", line 355, in import_app
    __import__(module)
  File "/var/www/compagnieinterface/sandbox/wsgi.py", line 16, in <module>
    application = get_wsgi_application()
  File "/root/.virtualenvs/compagnieinterface/lib/python3.4/site-packages/django/core/wsgi.py", line 14, in get_wsgi_application
    django.setup()
  File "/root/.virtualenvs/compagnieinterface/lib/python3.4/site-packages/django/__init__.py", line 17, in setup
    configure_logging(settings.LOGGING_CONFIG, settings.LOGGING)
  File "/root/.virtualenvs/compagnieinterface/lib/python3.4/site-packages/django/conf/__init__.py", line 48, in __getattr__
    self._setup(name)
  File "/root/.virtualenvs/compagnieinterface/lib/python3.4/site-packages/django/conf/__init__.py", line 44, in _setup
    self._wrapped = Settings(settings_module)
  File "/root/.virtualenvs/compagnieinterface/lib/python3.4/site-packages/django/conf/__init__.py", line 92, in __init__
    mod = importlib.import_module(self.SETTINGS_MODULE)
  File "/root/.virtualenvs/compagnieinterface/lib/python3.4/importlib/__init__.py", line 109, in import_module
    return _bootstrap._gcd_import(name[level:], package, level)
  File "/var/www/compagnieinterface/sandbox/settings.py", line 144
    ]
    ^
SyntaxError: invalid syntax
[2016-01-16 09:57:14 -0500] [9269] [INFO] Worker exiting (pid: 9269)
Traceback (most recent call last):
  File "/root/.virtualenvs/compagnieinterface/lib/python3.4/site-packages/gunicorn/arbiter.py", line 179, in run
    self.sleep()
  File "/root/.virtualenvs/compagnieinterface/lib/python3.4/site-packages/gunicorn/arbiter.py", line 312, in sleep
    ready = select.select([self.PIPE[0]], [], [], 1.0)
  File "/root/.virtualenvs/compagnieinterface/lib/python3.4/site-packages/gunicorn/arbiter.py", line 214, in handle_chld
    self.reap_workers()
  File "/root/.virtualenvs/compagnieinterface/lib/python3.4/site-packages/gunicorn/arbiter.py", line 459, in reap_workers
    raise HaltServer(reason, self.WORKER_BOOT_ERROR)
gunicorn.errors.HaltServer: <HaltServer 'Worker failed to boot.' 3>

During handling of the above exception, another exception occurred:

Traceback (most recent call last):
  File "/root/.virtualenvs/compagnieinterface/bin/gunicorn", line 11, in <module>
    sys.exit(run())
  File "/root/.virtualenvs/compagnieinterface/lib/python3.4/site-packages/gunicorn/app/wsgiapp.py", line 74, in run
    WSGIApplication("%(prog)s [OPTIONS] [APP_MODULE]").run()
  File "/root/.virtualenvs/compagnieinterface/lib/python3.4/site-packages/gunicorn/app/base.py", line 189, in run
    super(Application, self).run()
  File "/root/.virtualenvs/compagnieinterface/lib/python3.4/site-packages/gunicorn/app/base.py", line 72, in run
    Arbiter(self).run()
  File "/root/.virtualenvs/compagnieinterface/lib/python3.4/site-packages/gunicorn/arbiter.py", line 201, in run
    self.halt(reason=inst.reason, exit_status=inst.exit_status)
  File "/root/.virtualenvs/compagnieinterface/lib/python3.4/site-packages/gunicorn/arbiter.py", line 297, in halt
    self.stop()
  File "/root/.virtualenvs/compagnieinterface/lib/python3.4/site-packages/gunicorn/arbiter.py", line 342, in stop
    time.sleep(0.1)
  File "/root/.virtualenvs/compagnieinterface/lib/python3.4/site-packages/gunicorn/arbiter.py", line 214, in handle_chld
    self.reap_workers()
  File "/root/.virtualenvs/compagnieinterface/lib/python3.4/site-packages/gunicorn/arbiter.py", line 459, in reap_workers
    raise HaltServer(reason, self.WORKER_BOOT_ERROR)
gunicorn.errors.HaltServer: <HaltServer 'Worker failed to boot.' 3>
[2016-01-16 10:02:11 -0500] [9622] [INFO] Starting gunicorn 19.3.0
[2016-01-16 10:02:11 -0500] [9622] [INFO] Listening at: http://127.0.0.1:8005 (9622)
[2016-01-16 10:02:11 -0500] [9622] [INFO] Using worker: sync
[2016-01-16 10:02:11 -0500] [9627] [INFO] Booting worker with pid: 9627
[2016-01-16 10:02:11 -0500] [9628] [INFO] Booting worker with pid: 9628
[2016-01-16 10:02:11 -0500] [9629] [INFO] Booting worker with pid: 9629
[2016-01-17 04:52:46 -0500] [9622] [INFO] Handling signal: term
[2016-01-17 09:52:46 +0000] [9627] [INFO] Worker exiting (pid: 9627)
[2016-01-17 09:52:46 +0000] [9628] [INFO] Worker exiting (pid: 9628)
[2016-01-17 09:52:46 +0000] [9629] [INFO] Worker exiting (pid: 9629)
[2016-01-17 04:52:47 -0500] [9622] [INFO] Shutting down: Master
[2016-01-17 04:52:49 -0500] [17586] [INFO] Starting gunicorn 19.3.0
[2016-01-17 04:52:49 -0500] [17586] [INFO] Listening at: http://127.0.0.1:8005 (17586)
[2016-01-17 04:52:49 -0500] [17586] [INFO] Using worker: sync
[2016-01-17 04:52:49 -0500] [17591] [INFO] Booting worker with pid: 17591
[2016-01-17 04:52:49 -0500] [17592] [INFO] Booting worker with pid: 17592
[2016-01-17 04:52:49 -0500] [17593] [INFO] Booting worker with pid: 17593
[2016-01-19 09:49:19 -0500] [17586] [INFO] Handling signal: term
[2016-01-19 14:49:19 +0000] [17592] [INFO] Worker exiting (pid: 17592)
[2016-01-19 14:49:19 +0000] [17593] [INFO] Worker exiting (pid: 17593)
[2016-01-19 14:49:19 +0000] [17591] [INFO] Worker exiting (pid: 17591)
[2016-01-19 09:49:20 -0500] [17586] [INFO] Shutting down: Master
[2016-01-19 09:49:21 -0500] [8394] [INFO] Starting gunicorn 19.3.0
[2016-01-19 09:49:21 -0500] [8394] [INFO] Listening at: http://127.0.0.1:8005 (8394)
[2016-01-19 09:49:21 -0500] [8394] [INFO] Using worker: sync
[2016-01-19 09:49:21 -0500] [8399] [INFO] Booting worker with pid: 8399
[2016-01-19 09:49:21 -0500] [8400] [INFO] Booting worker with pid: 8400
[2016-01-19 09:49:21 -0500] [8401] [INFO] Booting worker with pid: 8401
[2016-01-19 09:50:18 -0500] [8394] [INFO] Handling signal: term
[2016-01-19 14:50:18 +0000] [8400] [INFO] Worker exiting (pid: 8400)
[2016-01-19 14:50:18 +0000] [8401] [INFO] Worker exiting (pid: 8401)
[2016-01-19 14:50:18 +0000] [8399] [INFO] Worker exiting (pid: 8399)
[2016-01-19 09:50:18 -0500] [8394] [INFO] Shutting down: Master
[2016-01-19 09:50:19 -0500] [8495] [INFO] Starting gunicorn 19.3.0
[2016-01-19 09:50:19 -0500] [8495] [INFO] Listening at: http://127.0.0.1:8005 (8495)
[2016-01-19 09:50:19 -0500] [8495] [INFO] Using worker: sync
[2016-01-19 09:50:19 -0500] [8500] [INFO] Booting worker with pid: 8500
[2016-01-19 09:50:19 -0500] [8501] [INFO] Booting worker with pid: 8501
[2016-01-19 09:50:19 -0500] [8503] [INFO] Booting worker with pid: 8503
[2016-01-21 08:56:54 -0500] [8495] [INFO] Handling signal: term
[2016-01-21 13:56:54 +0000] [8503] [INFO] Worker exiting (pid: 8503)
[2016-01-21 13:56:54 +0000] [8501] [INFO] Worker exiting (pid: 8501)
[2016-01-21 13:56:54 +0000] [8500] [INFO] Worker exiting (pid: 8500)
[2016-01-21 08:56:56 -0500] [8495] [INFO] Shutting down: Master
[2016-01-21 08:57:41 -0500] [1535] [INFO] Starting gunicorn 19.3.0
[2016-01-21 08:57:41 -0500] [1535] [INFO] Listening at: http://127.0.0.1:8005 (1535)
[2016-01-21 08:57:41 -0500] [1535] [INFO] Using worker: sync
[2016-01-21 08:57:41 -0500] [1652] [INFO] Booting worker with pid: 1652
[2016-01-21 08:57:42 -0500] [1653] [INFO] Booting worker with pid: 1653
[2016-01-21 08:57:42 -0500] [1657] [INFO] Booting worker with pid: 1657
[2016-01-21 13:57:44 +0000] [1653] [ERROR] Exception in worker process:
Traceback (most recent call last):
  File "/root/.virtualenvs/compagnieinterface/lib/python3.4/site-packages/gunicorn/arbiter.py", line 507, in spawn_worker
    worker.init_process()
  File "/root/.virtualenvs/compagnieinterface/lib/python3.4/site-packages/gunicorn/workers/base.py", line 118, in init_process
    self.wsgi = self.app.wsgi()
  File "/root/.virtualenvs/compagnieinterface/lib/python3.4/site-packages/gunicorn/app/base.py", line 67, in wsgi
    self.callable = self.load()
  File "/root/.virtualenvs/compagnieinterface/lib/python3.4/site-packages/gunicorn/app/wsgiapp.py", line 65, in load
    return self.load_wsgiapp()
  File "/root/.virtualenvs/compagnieinterface/lib/python3.4/site-packages/gunicorn/app/wsgiapp.py", line 52, in load_wsgiapp
    return util.import_app(self.app_uri)
  File "/root/.virtualenvs/compagnieinterface/lib/python3.4/site-packages/gunicorn/util.py", line 355, in import_app
    __import__(module)
  File "/var/www/compagnieinterface/sandbox/wsgi.py", line 16, in <module>
    application = get_wsgi_application()
  File "/root/.virtualenvs/compagnieinterface/lib/python3.4/site-packages/django/core/wsgi.py", line 14, in get_wsgi_application
    django.setup()
  File "/root/.virtualenvs/compagnieinterface/lib/python3.4/site-packages/django/__init__.py", line 18, in setup
    apps.populate(settings.INSTALLED_APPS)
  File "/root/.virtualenvs/compagnieinterface/lib/python3.4/site-packages/django/apps/registry.py", line 85, in populate
    app_config = AppConfig.create(entry)
  File "/root/.virtualenvs/compagnieinterface/lib/python3.4/site-packages/django/apps/config.py", line 86, in create
    module = import_module(entry)
  File "/root/.virtualenvs/compagnieinterface/lib/python3.4/importlib/__init__.py", line 109, in import_module
    return _bootstrap._gcd_import(name[level:], package, level)
ImportError: No module named 'debug_toolbar'
Traceback (most recent call last):
  File "/root/.virtualenvs/compagnieinterface/lib/python3.4/site-packages/gunicorn/arbiter.py", line 507, in spawn_worker
    worker.init_process()
  File "/root/.virtualenvs/compagnieinterface/lib/python3.4/site-packages/gunicorn/workers/base.py", line 118, in init_process
    self.wsgi = self.app.wsgi()
  File "/root/.virtualenvs/compagnieinterface/lib/python3.4/site-packages/gunicorn/app/base.py", line 67, in wsgi
    self.callable = self.load()
  File "/root/.virtualenvs/compagnieinterface/lib/python3.4/site-packages/gunicorn/app/wsgiapp.py", line 65, in load
    return self.load_wsgiapp()
  File "/root/.virtualenvs/compagnieinterface/lib/python3.4/site-packages/gunicorn/app/wsgiapp.py", line 52, in load_wsgiapp
    return util.import_app(self.app_uri)
  File "/root/.virtualenvs/compagnieinterface/lib/python3.4/site-packages/gunicorn/util.py", line 355, in import_app
    __import__(module)
  File "/var/www/compagnieinterface/sandbox/wsgi.py", line 16, in <module>
    application = get_wsgi_application()
  File "/root/.virtualenvs/compagnieinterface/lib/python3.4/site-packages/django/core/wsgi.py", line 14, in get_wsgi_application
    django.setup()
  File "/root/.virtualenvs/compagnieinterface/lib/python3.4/site-packages/django/__init__.py", line 18, in setup
    apps.populate(settings.INSTALLED_APPS)
  File "/root/.virtualenvs/compagnieinterface/lib/python3.4/site-packages/django/apps/registry.py", line 85, in populate
    app_config = AppConfig.create(entry)
  File "/root/.virtualenvs/compagnieinterface/lib/python3.4/site-packages/django/apps/config.py", line 86, in create
    module = import_module(entry)
  File "/root/.virtualenvs/compagnieinterface/lib/python3.4/importlib/__init__.py", line 109, in import_module
    return _bootstrap._gcd_import(name[level:], package, level)
ImportError: No module named 'debug_toolbar'
[2016-01-21 13:57:44 +0000] [1652] [ERROR] Exception in worker process:
Traceback (most recent call last):
  File "/root/.virtualenvs/compagnieinterface/lib/python3.4/site-packages/gunicorn/arbiter.py", line 507, in spawn_worker
    worker.init_process()
  File "/root/.virtualenvs/compagnieinterface/lib/python3.4/site-packages/gunicorn/workers/base.py", line 118, in init_process
    self.wsgi = self.app.wsgi()
  File "/root/.virtualenvs/compagnieinterface/lib/python3.4/site-packages/gunicorn/app/base.py", line 67, in wsgi
    self.callable = self.load()
  File "/root/.virtualenvs/compagnieinterface/lib/python3.4/site-packages/gunicorn/app/wsgiapp.py", line 65, in load
    return self.load_wsgiapp()
  File "/root/.virtualenvs/compagnieinterface/lib/python3.4/site-packages/gunicorn/app/wsgiapp.py", line 52, in load_wsgiapp
    return util.import_app(self.app_uri)
  File "/root/.virtualenvs/compagnieinterface/lib/python3.4/site-packages/gunicorn/util.py", line 355, in import_app
    __import__(module)
  File "/var/www/compagnieinterface/sandbox/wsgi.py", line 16, in <module>
    application = get_wsgi_application()
  File "/root/.virtualenvs/compagnieinterface/lib/python3.4/site-packages/django/core/wsgi.py", line 14, in get_wsgi_application
    django.setup()
  File "/root/.virtualenvs/compagnieinterface/lib/python3.4/site-packages/django/__init__.py", line 18, in setup
    apps.populate(settings.INSTALLED_APPS)
  File "/root/.virtualenvs/compagnieinterface/lib/python3.4/site-packages/django/apps/registry.py", line 85, in populate
    app_config = AppConfig.create(entry)
  File "/root/.virtualenvs/compagnieinterface/lib/python3.4/site-packages/django/apps/config.py", line 86, in create
    module = import_module(entry)
  File "/root/.virtualenvs/compagnieinterface/lib/python3.4/importlib/__init__.py", line 109, in import_module
    return _bootstrap._gcd_import(name[level:], package, level)
ImportError: No module named 'debug_toolbar'
Traceback (most recent call last):
  File "/root/.virtualenvs/compagnieinterface/lib/python3.4/site-packages/gunicorn/arbiter.py", line 507, in spawn_worker
    worker.init_process()
  File "/root/.virtualenvs/compagnieinterface/lib/python3.4/site-packages/gunicorn/workers/base.py", line 118, in init_process
    self.wsgi = self.app.wsgi()
  File "/root/.virtualenvs/compagnieinterface/lib/python3.4/site-packages/gunicorn/app/base.py", line 67, in wsgi
    self.callable = self.load()
  File "/root/.virtualenvs/compagnieinterface/lib/python3.4/site-packages/gunicorn/app/wsgiapp.py", line 65, in load
    return self.load_wsgiapp()
  File "/root/.virtualenvs/compagnieinterface/lib/python3.4/site-packages/gunicorn/app/wsgiapp.py", line 52, in load_wsgiapp
    return util.import_app(self.app_uri)
  File "/root/.virtualenvs/compagnieinterface/lib/python3.4/site-packages/gunicorn/util.py", line 355, in import_app
    __import__(module)
  File "/var/www/compagnieinterface/sandbox/wsgi.py", line 16, in <module>
    application = get_wsgi_application()
  File "/root/.virtualenvs/compagnieinterface/lib/python3.4/site-packages/django/core/wsgi.py", line 14, in get_wsgi_application
    django.setup()
  File "/root/.virtualenvs/compagnieinterface/lib/python3.4/site-packages/django/__init__.py", line 18, in setup
    apps.populate(settings.INSTALLED_APPS)
  File "/root/.virtualenvs/compagnieinterface/lib/python3.4/site-packages/django/apps/registry.py", line 85, in populate
    app_config = AppConfig.create(entry)
  File "/root/.virtualenvs/compagnieinterface/lib/python3.4/site-packages/django/apps/config.py", line 86, in create
    module = import_module(entry)
  File "/root/.virtualenvs/compagnieinterface/lib/python3.4/importlib/__init__.py", line 109, in import_module
    return _bootstrap._gcd_import(name[level:], package, level)
ImportError: No module named 'debug_toolbar'
[2016-01-21 13:57:44 +0000] [1657] [ERROR] Exception in worker process:
Traceback (most recent call last):
  File "/root/.virtualenvs/compagnieinterface/lib/python3.4/site-packages/gunicorn/arbiter.py", line 507, in spawn_worker
    worker.init_process()
  File "/root/.virtualenvs/compagnieinterface/lib/python3.4/site-packages/gunicorn/workers/base.py", line 118, in init_process
    self.wsgi = self.app.wsgi()
  File "/root/.virtualenvs/compagnieinterface/lib/python3.4/site-packages/gunicorn/app/base.py", line 67, in wsgi
    self.callable = self.load()
  File "/root/.virtualenvs/compagnieinterface/lib/python3.4/site-packages/gunicorn/app/wsgiapp.py", line 65, in load
    return self.load_wsgiapp()
  File "/root/.virtualenvs/compagnieinterface/lib/python3.4/site-packages/gunicorn/app/wsgiapp.py", line 52, in load_wsgiapp
    return util.import_app(self.app_uri)
  File "/root/.virtualenvs/compagnieinterface/lib/python3.4/site-packages/gunicorn/util.py", line 355, in import_app
    __import__(module)
  File "/var/www/compagnieinterface/sandbox/wsgi.py", line 16, in <module>
    application = get_wsgi_application()
  File "/root/.virtualenvs/compagnieinterface/lib/python3.4/site-packages/django/core/wsgi.py", line 14, in get_wsgi_application
    django.setup()
  File "/root/.virtualenvs/compagnieinterface/lib/python3.4/site-packages/django/__init__.py", line 18, in setup
    apps.populate(settings.INSTALLED_APPS)
  File "/root/.virtualenvs/compagnieinterface/lib/python3.4/site-packages/django/apps/registry.py", line 85, in populate
    app_config = AppConfig.create(entry)
  File "/root/.virtualenvs/compagnieinterface/lib/python3.4/site-packages/django/apps/config.py", line 86, in create
    module = import_module(entry)
  File "/root/.virtualenvs/compagnieinterface/lib/python3.4/importlib/__init__.py", line 109, in import_module
    return _bootstrap._gcd_import(name[level:], package, level)
ImportError: No module named 'debug_toolbar'
Traceback (most recent call last):
  File "/root/.virtualenvs/compagnieinterface/lib/python3.4/site-packages/gunicorn/arbiter.py", line 507, in spawn_worker
    worker.init_process()
  File "/root/.virtualenvs/compagnieinterface/lib/python3.4/site-packages/gunicorn/workers/base.py", line 118, in init_process
    self.wsgi = self.app.wsgi()
  File "/root/.virtualenvs/compagnieinterface/lib/python3.4/site-packages/gunicorn/app/base.py", line 67, in wsgi
    self.callable = self.load()
  File "/root/.virtualenvs/compagnieinterface/lib/python3.4/site-packages/gunicorn/app/wsgiapp.py", line 65, in load
    return self.load_wsgiapp()
  File "/root/.virtualenvs/compagnieinterface/lib/python3.4/site-packages/gunicorn/app/wsgiapp.py", line 52, in load_wsgiapp
    return util.import_app(self.app_uri)
  File "/root/.virtualenvs/compagnieinterface/lib/python3.4/site-packages/gunicorn/util.py", line 355, in import_app
    __import__(module)
  File "/var/www/compagnieinterface/sandbox/wsgi.py", line 16, in <module>
    application = get_wsgi_application()
  File "/root/.virtualenvs/compagnieinterface/lib/python3.4/site-packages/django/core/wsgi.py", line 14, in get_wsgi_application
    django.setup()
  File "/root/.virtualenvs/compagnieinterface/lib/python3.4/site-packages/django/__init__.py", line 18, in setup
    apps.populate(settings.INSTALLED_APPS)
  File "/root/.virtualenvs/compagnieinterface/lib/python3.4/site-packages/django/apps/registry.py", line 85, in populate
    app_config = AppConfig.create(entry)
  File "/root/.virtualenvs/compagnieinterface/lib/python3.4/site-packages/django/apps/config.py", line 86, in create
    module = import_module(entry)
  File "/root/.virtualenvs/compagnieinterface/lib/python3.4/importlib/__init__.py", line 109, in import_module
    return _bootstrap._gcd_import(name[level:], package, level)
ImportError: No module named 'debug_toolbar'
[2016-01-21 13:57:44 +0000] [1653] [INFO] Worker exiting (pid: 1653)
[2016-01-21 13:57:44 +0000] [1657] [INFO] Worker exiting (pid: 1657)
[2016-01-21 13:57:44 +0000] [1652] [INFO] Worker exiting (pid: 1652)
[2016-01-21 08:57:45 -0500] [1535] [INFO] Shutting down: Master
[2016-01-21 08:57:45 -0500] [1535] [INFO] Reason: Worker failed to boot.
[2016-01-21 08:58:26 -0500] [1960] [INFO] Starting gunicorn 19.3.0
[2016-01-21 08:58:26 -0500] [1960] [INFO] Listening at: http://127.0.0.1:8005 (1960)
[2016-01-21 08:58:26 -0500] [1960] [INFO] Using worker: sync
[2016-01-21 08:58:26 -0500] [1965] [INFO] Booting worker with pid: 1965
[2016-01-21 08:58:26 -0500] [1966] [INFO] Booting worker with pid: 1966
[2016-01-21 08:58:26 -0500] [1967] [INFO] Booting worker with pid: 1967
[2016-01-21 13:58:27 +0000] [1965] [ERROR] Exception in worker process:
Traceback (most recent call last):
  File "/root/.virtualenvs/compagnieinterface/lib/python3.4/site-packages/gunicorn/arbiter.py", line 507, in spawn_worker
    worker.init_process()
  File "/root/.virtualenvs/compagnieinterface/lib/python3.4/site-packages/gunicorn/workers/base.py", line 118, in init_process
    self.wsgi = self.app.wsgi()
  File "/root/.virtualenvs/compagnieinterface/lib/python3.4/site-packages/gunicorn/app/base.py", line 67, in wsgi
    self.callable = self.load()
  File "/root/.virtualenvs/compagnieinterface/lib/python3.4/site-packages/gunicorn/app/wsgiapp.py", line 65, in load
    return self.load_wsgiapp()
  File "/root/.virtualenvs/compagnieinterface/lib/python3.4/site-packages/gunicorn/app/wsgiapp.py", line 52, in load_wsgiapp
    return util.import_app(self.app_uri)
  File "/root/.virtualenvs/compagnieinterface/lib/python3.4/site-packages/gunicorn/util.py", line 355, in import_app
    __import__(module)
  File "/var/www/compagnieinterface/sandbox/wsgi.py", line 16, in <module>
    application = get_wsgi_application()
  File "/root/.virtualenvs/compagnieinterface/lib/python3.4/site-packages/django/core/wsgi.py", line 14, in get_wsgi_application
    django.setup()
  File "/root/.virtualenvs/compagnieinterface/lib/python3.4/site-packages/django/__init__.py", line 18, in setup
    apps.populate(settings.INSTALLED_APPS)
  File "/root/.virtualenvs/compagnieinterface/lib/python3.4/site-packages/django/apps/registry.py", line 85, in populate
    app_config = AppConfig.create(entry)
  File "/root/.virtualenvs/compagnieinterface/lib/python3.4/site-packages/django/apps/config.py", line 86, in create
    module = import_module(entry)
  File "/root/.virtualenvs/compagnieinterface/lib/python3.4/importlib/__init__.py", line 109, in import_module
    return _bootstrap._gcd_import(name[level:], package, level)
ImportError: No module named 'debug_toolbar'
Traceback (most recent call last):
  File "/root/.virtualenvs/compagnieinterface/lib/python3.4/site-packages/gunicorn/arbiter.py", line 507, in spawn_worker
    worker.init_process()
  File "/root/.virtualenvs/compagnieinterface/lib/python3.4/site-packages/gunicorn/workers/base.py", line 118, in init_process
    self.wsgi = self.app.wsgi()
  File "/root/.virtualenvs/compagnieinterface/lib/python3.4/site-packages/gunicorn/app/base.py", line 67, in wsgi
    self.callable = self.load()
  File "/root/.virtualenvs/compagnieinterface/lib/python3.4/site-packages/gunicorn/app/wsgiapp.py", line 65, in load
    return self.load_wsgiapp()
  File "/root/.virtualenvs/compagnieinterface/lib/python3.4/site-packages/gunicorn/app/wsgiapp.py", line 52, in load_wsgiapp
    return util.import_app(self.app_uri)
  File "/root/.virtualenvs/compagnieinterface/lib/python3.4/site-packages/gunicorn/util.py", line 355, in import_app
    __import__(module)
  File "/var/www/compagnieinterface/sandbox/wsgi.py", line 16, in <module>
    application = get_wsgi_application()
  File "/root/.virtualenvs/compagnieinterface/lib/python3.4/site-packages/django/core/wsgi.py", line 14, in get_wsgi_application
    django.setup()
  File "/root/.virtualenvs/compagnieinterface/lib/python3.4/site-packages/django/__init__.py", line 18, in setup
    apps.populate(settings.INSTALLED_APPS)
  File "/root/.virtualenvs/compagnieinterface/lib/python3.4/site-packages/django/apps/registry.py", line 85, in populate
    app_config = AppConfig.create(entry)
  File "/root/.virtualenvs/compagnieinterface/lib/python3.4/site-packages/django/apps/config.py", line 86, in create
    module = import_module(entry)
  File "/root/.virtualenvs/compagnieinterface/lib/python3.4/importlib/__init__.py", line 109, in import_module
    return _bootstrap._gcd_import(name[level:], package, level)
ImportError: No module named 'debug_toolbar'
[2016-01-21 13:58:27 +0000] [1965] [INFO] Worker exiting (pid: 1965)
[2016-01-21 13:58:28 +0000] [1966] [ERROR] Exception in worker process:
Traceback (most recent call last):
  File "/root/.virtualenvs/compagnieinterface/lib/python3.4/site-packages/gunicorn/arbiter.py", line 507, in spawn_worker
    worker.init_process()
  File "/root/.virtualenvs/compagnieinterface/lib/python3.4/site-packages/gunicorn/workers/base.py", line 118, in init_process
    self.wsgi = self.app.wsgi()
  File "/root/.virtualenvs/compagnieinterface/lib/python3.4/site-packages/gunicorn/app/base.py", line 67, in wsgi
    self.callable = self.load()
  File "/root/.virtualenvs/compagnieinterface/lib/python3.4/site-packages/gunicorn/app/wsgiapp.py", line 65, in load
    return self.load_wsgiapp()
  File "/root/.virtualenvs/compagnieinterface/lib/python3.4/site-packages/gunicorn/app/wsgiapp.py", line 52, in load_wsgiapp
    return util.import_app(self.app_uri)
  File "/root/.virtualenvs/compagnieinterface/lib/python3.4/site-packages/gunicorn/util.py", line 355, in import_app
    __import__(module)
  File "/var/www/compagnieinterface/sandbox/wsgi.py", line 16, in <module>
    application = get_wsgi_application()
  File "/root/.virtualenvs/compagnieinterface/lib/python3.4/site-packages/django/core/wsgi.py", line 14, in get_wsgi_application
    django.setup()
  File "/root/.virtualenvs/compagnieinterface/lib/python3.4/site-packages/django/__init__.py", line 18, in setup
    apps.populate(settings.INSTALLED_APPS)
  File "/root/.virtualenvs/compagnieinterface/lib/python3.4/site-packages/django/apps/registry.py", line 85, in populate
    app_config = AppConfig.create(entry)
  File "/root/.virtualenvs/compagnieinterface/lib/python3.4/site-packages/django/apps/config.py", line 86, in create
    module = import_module(entry)
  File "/root/.virtualenvs/compagnieinterface/lib/python3.4/importlib/__init__.py", line 109, in import_module
    return _bootstrap._gcd_import(name[level:], package, level)
ImportError: No module named 'debug_toolbar'
Traceback (most recent call last):
  File "/root/.virtualenvs/compagnieinterface/lib/python3.4/site-packages/gunicorn/arbiter.py", line 507, in spawn_worker
    worker.init_process()
  File "/root/.virtualenvs/compagnieinterface/lib/python3.4/site-packages/gunicorn/workers/base.py", line 118, in init_process
    self.wsgi = self.app.wsgi()
  File "/root/.virtualenvs/compagnieinterface/lib/python3.4/site-packages/gunicorn/app/base.py", line 67, in wsgi
    self.callable = self.load()
  File "/root/.virtualenvs/compagnieinterface/lib/python3.4/site-packages/gunicorn/app/wsgiapp.py", line 65, in load
    return self.load_wsgiapp()
  File "/root/.virtualenvs/compagnieinterface/lib/python3.4/site-packages/gunicorn/app/wsgiapp.py", line 52, in load_wsgiapp
    return util.import_app(self.app_uri)
  File "/root/.virtualenvs/compagnieinterface/lib/python3.4/site-packages/gunicorn/util.py", line 355, in import_app
    __import__(module)
  File "/var/www/compagnieinterface/sandbox/wsgi.py", line 16, in <module>
    application = get_wsgi_application()
  File "/root/.virtualenvs/compagnieinterface/lib/python3.4/site-packages/django/core/wsgi.py", line 14, in get_wsgi_application
    django.setup()
  File "/root/.virtualenvs/compagnieinterface/lib/python3.4/site-packages/django/__init__.py", line 18, in setup
    apps.populate(settings.INSTALLED_APPS)
  File "/root/.virtualenvs/compagnieinterface/lib/python3.4/site-packages/django/apps/registry.py", line 85, in populate
    app_config = AppConfig.create(entry)
  File "/root/.virtualenvs/compagnieinterface/lib/python3.4/site-packages/django/apps/config.py", line 86, in create
    module = import_module(entry)
  File "/root/.virtualenvs/compagnieinterface/lib/python3.4/importlib/__init__.py", line 109, in import_module
    return _bootstrap._gcd_import(name[level:], package, level)
ImportError: No module named 'debug_toolbar'
[2016-01-21 13:58:28 +0000] [1966] [INFO] Worker exiting (pid: 1966)
[2016-01-21 13:58:28 +0000] [1967] [ERROR] Exception in worker process:
Traceback (most recent call last):
  File "/root/.virtualenvs/compagnieinterface/lib/python3.4/site-packages/gunicorn/arbiter.py", line 507, in spawn_worker
    worker.init_process()
  File "/root/.virtualenvs/compagnieinterface/lib/python3.4/site-packages/gunicorn/workers/base.py", line 118, in init_process
    self.wsgi = self.app.wsgi()
  File "/root/.virtualenvs/compagnieinterface/lib/python3.4/site-packages/gunicorn/app/base.py", line 67, in wsgi
    self.callable = self.load()
  File "/root/.virtualenvs/compagnieinterface/lib/python3.4/site-packages/gunicorn/app/wsgiapp.py", line 65, in load
    return self.load_wsgiapp()
  File "/root/.virtualenvs/compagnieinterface/lib/python3.4/site-packages/gunicorn/app/wsgiapp.py", line 52, in load_wsgiapp
    return util.import_app(self.app_uri)
  File "/root/.virtualenvs/compagnieinterface/lib/python3.4/site-packages/gunicorn/util.py", line 355, in import_app
    __import__(module)
  File "/var/www/compagnieinterface/sandbox/wsgi.py", line 16, in <module>
    application = get_wsgi_application()
  File "/root/.virtualenvs/compagnieinterface/lib/python3.4/site-packages/django/core/wsgi.py", line 14, in get_wsgi_application
    django.setup()
  File "/root/.virtualenvs/compagnieinterface/lib/python3.4/site-packages/django/__init__.py", line 18, in setup
    apps.populate(settings.INSTALLED_APPS)
  File "/root/.virtualenvs/compagnieinterface/lib/python3.4/site-packages/django/apps/registry.py", line 85, in populate
    app_config = AppConfig.create(entry)
  File "/root/.virtualenvs/compagnieinterface/lib/python3.4/site-packages/django/apps/config.py", line 86, in create
    module = import_module(entry)
  File "/root/.virtualenvs/compagnieinterface/lib/python3.4/importlib/__init__.py", line 109, in import_module
    return _bootstrap._gcd_import(name[level:], package, level)
ImportError: No module named 'debug_toolbar'
Traceback (most recent call last):
  File "/root/.virtualenvs/compagnieinterface/lib/python3.4/site-packages/gunicorn/arbiter.py", line 507, in spawn_worker
    worker.init_process()
  File "/root/.virtualenvs/compagnieinterface/lib/python3.4/site-packages/gunicorn/workers/base.py", line 118, in init_process
    self.wsgi = self.app.wsgi()
  File "/root/.virtualenvs/compagnieinterface/lib/python3.4/site-packages/gunicorn/app/base.py", line 67, in wsgi
    self.callable = self.load()
  File "/root/.virtualenvs/compagnieinterface/lib/python3.4/site-packages/gunicorn/app/wsgiapp.py", line 65, in load
    return self.load_wsgiapp()
  File "/root/.virtualenvs/compagnieinterface/lib/python3.4/site-packages/gunicorn/app/wsgiapp.py", line 52, in load_wsgiapp
    return util.import_app(self.app_uri)
  File "/root/.virtualenvs/compagnieinterface/lib/python3.4/site-packages/gunicorn/util.py", line 355, in import_app
    __import__(module)
  File "/var/www/compagnieinterface/sandbox/wsgi.py", line 16, in <module>
    application = get_wsgi_application()
  File "/root/.virtualenvs/compagnieinterface/lib/python3.4/site-packages/django/core/wsgi.py", line 14, in get_wsgi_application
    django.setup()
  File "/root/.virtualenvs/compagnieinterface/lib/python3.4/site-packages/django/__init__.py", line 18, in setup
    apps.populate(settings.INSTALLED_APPS)
  File "/root/.virtualenvs/compagnieinterface/lib/python3.4/site-packages/django/apps/registry.py", line 85, in populate
    app_config = AppConfig.create(entry)
  File "/root/.virtualenvs/compagnieinterface/lib/python3.4/site-packages/django/apps/config.py", line 86, in create
    module = import_module(entry)
  File "/root/.virtualenvs/compagnieinterface/lib/python3.4/importlib/__init__.py", line 109, in import_module
    return _bootstrap._gcd_import(name[level:], package, level)
ImportError: No module named 'debug_toolbar'
[2016-01-21 13:58:28 +0000] [1967] [INFO] Worker exiting (pid: 1967)
[2016-01-21 08:58:28 -0500] [1960] [INFO] Shutting down: Master
[2016-01-21 08:58:28 -0500] [1960] [INFO] Reason: Worker failed to boot.
[2016-01-21 09:01:17 -0500] [2071] [INFO] Starting gunicorn 19.3.0
[2016-01-21 09:01:17 -0500] [2071] [INFO] Listening at: http://127.0.0.1:8005 (2071)
[2016-01-21 09:01:17 -0500] [2071] [INFO] Using worker: sync
[2016-01-21 09:01:17 -0500] [2076] [INFO] Booting worker with pid: 2076
[2016-01-21 09:01:17 -0500] [2077] [INFO] Booting worker with pid: 2077
[2016-01-21 09:01:17 -0500] [2078] [INFO] Booting worker with pid: 2078
[2016-01-21 09:01:41 -0500] [2071] [INFO] Handling signal: term
[2016-01-21 14:01:41 +0000] [2076] [INFO] Worker exiting (pid: 2076)
[2016-01-21 14:01:41 +0000] [2077] [INFO] Worker exiting (pid: 2077)
[2016-01-21 14:01:41 +0000] [2078] [INFO] Worker exiting (pid: 2078)
[2016-01-21 09:01:42 -0500] [2071] [INFO] Shutting down: Master
[2016-01-21 09:06:06 -0500] [1514] [INFO] Starting gunicorn 19.3.0
[2016-01-21 09:06:06 -0500] [1514] [INFO] Listening at: http://127.0.0.1:8005 (1514)
[2016-01-21 09:06:06 -0500] [1514] [INFO] Using worker: sync
[2016-01-21 09:06:06 -0500] [1623] [INFO] Booting worker with pid: 1623
[2016-01-21 09:06:06 -0500] [1624] [INFO] Booting worker with pid: 1624
[2016-01-21 09:06:06 -0500] [1625] [INFO] Booting worker with pid: 1625
[2016-01-26 03:59:32 -0500] [1514] [INFO] Handling signal: term
[2016-01-26 08:59:32 +0000] [1624] [INFO] Worker exiting (pid: 1624)
[2016-01-26 08:59:32 +0000] [1625] [INFO] Worker exiting (pid: 1625)
[2016-01-26 08:59:33 +0000] [1623] [INFO] Worker exiting (pid: 1623)
[2016-01-26 03:59:33 -0500] [1514] [INFO] Shutting down: Master
[2016-01-26 03:59:34 -0500] [1835] [INFO] Starting gunicorn 19.3.0
[2016-01-26 03:59:34 -0500] [1835] [INFO] Listening at: http://127.0.0.1:8005 (1835)
[2016-01-26 03:59:34 -0500] [1835] [INFO] Using worker: sync
[2016-01-26 03:59:34 -0500] [1840] [INFO] Booting worker with pid: 1840
[2016-01-26 03:59:34 -0500] [1841] [INFO] Booting worker with pid: 1841
[2016-01-26 03:59:34 -0500] [1842] [INFO] Booting worker with pid: 1842
[2016-01-26 04:02:28 -0500] [1835] [INFO] Handling signal: term
[2016-01-26 09:02:28 +0000] [1840] [INFO] Worker exiting (pid: 1840)
[2016-01-26 09:02:28 +0000] [1841] [INFO] Worker exiting (pid: 1841)
[2016-01-26 09:02:28 +0000] [1842] [INFO] Worker exiting (pid: 1842)
[2016-01-26 04:02:29 -0500] [1835] [INFO] Shutting down: Master
[2016-01-26 04:02:30 -0500] [1931] [INFO] Starting gunicorn 19.3.0
[2016-01-26 04:02:30 -0500] [1931] [INFO] Listening at: http://127.0.0.1:8005 (1931)
[2016-01-26 04:02:30 -0500] [1931] [INFO] Using worker: sync
[2016-01-26 04:02:30 -0500] [1936] [INFO] Booting worker with pid: 1936
[2016-01-26 04:02:30 -0500] [1937] [INFO] Booting worker with pid: 1937
[2016-01-26 04:02:30 -0500] [1938] [INFO] Booting worker with pid: 1938
[2016-01-31 11:30:45 -0500] [1931] [INFO] Handling signal: term
[2016-01-31 16:30:45 +0000] [1936] [INFO] Worker exiting (pid: 1936)
[2016-01-31 16:30:45 +0000] [1937] [INFO] Worker exiting (pid: 1937)
[2016-01-31 16:30:45 +0000] [1938] [INFO] Worker exiting (pid: 1938)
[2016-01-31 11:30:45 -0500] [1931] [INFO] Shutting down: Master
[2016-01-31 11:30:47 -0500] [28802] [INFO] Starting gunicorn 19.3.0
[2016-01-31 11:30:47 -0500] [28802] [INFO] Listening at: http://127.0.0.1:8005 (28802)
[2016-01-31 11:30:47 -0500] [28802] [INFO] Using worker: sync
[2016-01-31 11:30:47 -0500] [28807] [INFO] Booting worker with pid: 28807
[2016-01-31 11:30:47 -0500] [28808] [INFO] Booting worker with pid: 28808
[2016-01-31 11:30:47 -0500] [28809] [INFO] Booting worker with pid: 28809
